<?xml version="1.0" encoding="UTF-8"?>
<testng-results ignored="1" total="5" passed="3" failed="1" skipped="0">
  <reporter-output>
  </reporter-output>
  <suite started-at="2023-04-29T07:39:31 IST" name="Default suite" finished-at="2023-04-29T07:40:05 IST" duration-ms="33514">
    <groups>
    </groups>
    <test started-at="2023-04-29T07:39:31 IST" name="Default test" finished-at="2023-04-29T07:40:05 IST" duration-ms="33514">
      <class name="test.com.testR9">
        <test-method signature="Login2(java.lang.String,java.lang.String)[pri:0, instance:test.com.testR9@6dc17b83]" started-at="2023-04-29T07:39:32 IST" name="Login2" data-provider="loginData" finished-at="2023-04-29T07:39:42 IST" duration-ms="10516" status="PASS">
          <params>
            <param index="0">
              <value>
                <![CDATA[standard_user]]>
              </value>
            </param>
            <param index="1">
              <value>
                <![CDATA[secret_sauce]]>
              </value>
            </param>
          </params>
          <reporter-output>
          </reporter-output>
        </test-method> <!-- Login2 -->
        <test-method signature="Login2(java.lang.String,java.lang.String)[pri:0, instance:test.com.testR9@6dc17b83]" started-at="2023-04-29T07:39:42 IST" name="Login2" data-provider="loginData" finished-at="2023-04-29T07:39:47 IST" duration-ms="5218" status="FAIL">
          <params>
            <param index="0">
              <value>
                <![CDATA[locked_out_user]]>
              </value>
            </param>
            <param index="1">
              <value>
                <![CDATA[secret_sauce]]>
              </value>
            </param>
          </params>
          <exception class="java.lang.AssertionError">
            <message>
              <![CDATA[expected [6] but found [0]]]>
            </message>
            <full-stacktrace>
              <![CDATA[java.lang.AssertionError: expected [6] but found [0]
at org.testng.Assert.fail(Assert.java:99)
at org.testng.Assert.failNotEquals(Assert.java:1037)
at org.testng.Assert.assertEqualsImpl(Assert.java:140)
at org.testng.Assert.assertEquals(Assert.java:122)
at org.testng.Assert.assertEquals(Assert.java:907)
at org.testng.Assert.assertEquals(Assert.java:917)
at test.com.testR9.Login2(testR9.java:59)
at java.base/jdk.internal.reflect.DirectMethodHandleAccessor.invoke(DirectMethodHandleAccessor.java:104)
at java.base/java.lang.reflect.Method.invoke(Method.java:577)
at org.testng.internal.MethodInvocationHelper.invokeMethod(MethodInvocationHelper.java:133)
at org.testng.internal.TestInvoker.invokeMethod(TestInvoker.java:598)
at org.testng.internal.TestInvoker.invokeTestMethod(TestInvoker.java:173)
at org.testng.internal.MethodRunner.runInSequence(MethodRunner.java:46)
at org.testng.internal.TestInvoker$MethodInvocationAgent.invoke(TestInvoker.java:824)
at org.testng.internal.TestInvoker.invokeTestMethods(TestInvoker.java:146)
at org.testng.internal.TestMethodWorker.invokeTestMethods(TestMethodWorker.java:146)
at org.testng.internal.TestMethodWorker.run(TestMethodWorker.java:128)
at java.base/java.util.ArrayList.forEach(ArrayList.java:1511)
at org.testng.TestRunner.privateRun(TestRunner.java:794)
at org.testng.TestRunner.run(TestRunner.java:596)
at org.testng.SuiteRunner.runTest(SuiteRunner.java:377)
at org.testng.SuiteRunner.runSequentially(SuiteRunner.java:371)
at org.testng.SuiteRunner.privateRun(SuiteRunner.java:332)
at org.testng.SuiteRunner.run(SuiteRunner.java:276)
at org.testng.SuiteRunnerWorker.runSuite(SuiteRunnerWorker.java:53)
at org.testng.SuiteRunnerWorker.run(SuiteRunnerWorker.java:96)
at org.testng.TestNG.runSuitesSequentially(TestNG.java:1212)
at org.testng.TestNG.runSuitesLocally(TestNG.java:1134)
at org.testng.TestNG.runSuites(TestNG.java:1063)
at org.testng.TestNG.run(TestNG.java:1031)
at org.testng.remote.AbstractRemoteTestNG.run(AbstractRemoteTestNG.java:115)
at org.testng.remote.RemoteTestNG.initAndRun(RemoteTestNG.java:251)
at org.testng.remote.RemoteTestNG.main(RemoteTestNG.java:77)
]]>
            </full-stacktrace>
          </exception> <!-- java.lang.AssertionError -->
          <reporter-output>
          </reporter-output>
        </test-method> <!-- Login2 -->
        <test-method signature="Login2(java.lang.String,java.lang.String)[pri:0, instance:test.com.testR9@6dc17b83]" started-at="2023-04-29T07:39:47 IST" name="Login2" data-provider="loginData" finished-at="2023-04-29T07:39:53 IST" duration-ms="5980" status="PASS">
          <params>
            <param index="0">
              <value>
                <![CDATA[problem_user]]>
              </value>
            </param>
            <param index="1">
              <value>
                <![CDATA[secret_sauce]]>
              </value>
            </param>
          </params>
          <reporter-output>
          </reporter-output>
        </test-method> <!-- Login2 -->
        <test-method signature="Login2(java.lang.String,java.lang.String)[pri:0, instance:test.com.testR9@6dc17b83]" started-at="2023-04-29T07:39:53 IST" name="Login2" data-provider="loginData" finished-at="2023-04-29T07:40:05 IST" duration-ms="11611" status="PASS">
          <params>
            <param index="0">
              <value>
                <![CDATA[performance_glitch_user]]>
              </value>
            </param>
            <param index="1">
              <value>
                <![CDATA[secret_sauce]]>
              </value>
            </param>
          </params>
          <reporter-output>
          </reporter-output>
        </test-method> <!-- Login2 -->
      </class> <!-- test.com.testR9 -->
    </test> <!-- Default test -->
  </suite> <!-- Default suite -->
</testng-results>
